<?xml version="1.0" encoding="utf-8"?>
<!-- =================================================================================== -->
<!-- |    This document was autogenerated by xacro from em_3905_hokuyo_imu.urdf.xacro  | -->
<!-- |    EDITING THIS FILE BY HAND IS NOT RECOMMENDED                                 | -->
<!-- =================================================================================== -->
<!-- em_3905.urdf.xacro

This file defines a model of a Traxxas(R) E-Maxx(R) #3905 RC (Radio Controlled)
truck.

Lengths are measured in meters, angles are measured in radians, and masses are
measured in kilograms. All of these values are approximations.

To work with Gazebo, each link must have an inertial element, even if
the link only serves to connect two joints. To be visible in Gazebo, a link
must have a collision element. Furthermore, the link must have a Gazebo
material.

Traxxas(R), E-Maxx(R), and Titan(R) are registered trademarks of Traxxas
Management, LLC. em_3905.urdf.xacro was independently created by Wunderkammer
Laboratory, and neither em_3905.urdf.xacro nor Wunderkammer Laboratory is
affiliated with, sponsored by, approved by, or endorsed by Traxxas Management,
LLC. Mabuchi Motor(R) is a registered trademark of Mabuchi Motor Co., Ltd.
Corporation Japan. All other trademarks and service marks are the property of
their respective owners.

Copyright (c) 2011-2014 Wunderkammer Laboratory

Licensed under the Apache License, Version 2.0 (the "License");
you may not use this file except in compliance with the License.
You may obtain a copy of the License at

  http://www.apache.org/licenses/LICENSE-2.0

Unless required by applicable law or agreed to in writing, software
distributed under the License is distributed on an "AS IS" BASIS,
WITHOUT WARRANTIES OR CONDITIONS OF ANY KIND, either express or implied.
See the License for the specific language governing permissions and
limitations under the License.
-->
<robot name="em_3905">
  <material name="battery_mat">
    <color rgba="0 0 1 1"/>
  </material>
  <material name="chassis_mat">
    <color rgba="0.5 0.5 0.5 1"/>
  </material>
  <material name="tire_mat">
    <color rgba="0 0 0 1"/>
  </material>
  <!-- base_link must have geometry so that its axes can be displayed in
       rviz. -->
  <link name="base_link">
    <visual>
      <geometry>
        <box size="0.01 0.01 0.01"/>
      </geometry>
      <material name="chassis_mat"/>
    </visual>
  </link>
  <gazebo reference="base_link">
    <material>Gazebo/Grey</material>
  </gazebo>
  <!-- Chassis -->
  <link name="chassis">
    <visual>
      <origin xyz="0 0 -0.005"/>
      <geometry>
        <box size="0.258 0.168 0.01"/>
      </geometry>
      <material name="chassis_mat"/>
    </visual>
    <collision>
      <origin xyz="0 0 -0.005"/>
      <geometry>
        <box size="0.258 0.168 0.01"/>
      </geometry>
    </collision>
    <inertial>
      <origin xyz="0 0 -0.005"/>
      <mass value="2.788"/>
      <inertia ixx="0.00658060933333" ixy="0" ixz="0" iyy="0.0154882693333" iyz="0" izz="0.022022412"/>
    </inertial>
  </link>
  <gazebo reference="chassis">
    <material>Gazebo/Grey</material>
  </gazebo>
  <joint name="base_link_to_chassis" type="fixed">
    <parent link="base_link"/>
    <child link="chassis"/>
  </joint>
  <joint name="chassis_to_left_battery" type="fixed">
    <parent link="chassis"/>
    <child link="left_battery_offset"/>
    <origin rpy="0.34906585 0 0" xyz="-0.025                    0.0325                    0"/>
  </joint>
  <link name="left_battery_offset">
    <inertial>
      <mass value="0.001"/>
      <inertia ixx="0.001" ixy="0" ixz="0" iyy="0.001" iyz="0" izz="0.001"/>
    </inertial>
  </link>
  <joint name="offset_to_left_battery" type="fixed">
    <parent link="left_battery_offset"/>
    <child link="left_battery"/>
    <origin xyz="0                    0.0235                    -0.008"/>
  </joint>
  <link name="left_battery">
    <visual>
      <geometry>
        <box size="0.16 0.047 0.024"/>
      </geometry>
      <material name="battery_mat"/>
    </visual>
    <collision>
      <geometry>
        <box size="0.16 0.047 0.024"/>
      </geometry>
    </collision>
    <inertial>
      <origin/>
      <mass value="0.5025"/>
      <inertia ixx="0.000116621875" ixy="0" ixz="0" iyy="0.00109612" iyz="0" izz="0.001164501875"/>
    </inertial>
  </link>
  <gazebo reference="left_battery">
    <material>Gazebo/Blue</material>
  </gazebo>
  <joint name="chassis_to_right_battery" type="fixed">
    <parent link="chassis"/>
    <child link="right_battery_offset"/>
    <origin rpy="-0.34906585 0 0" xyz="-0.025                    -0.0325                    0"/>
  </joint>
  <link name="right_battery_offset">
    <inertial>
      <mass value="0.001"/>
      <inertia ixx="0.001" ixy="0" ixz="0" iyy="0.001" iyz="0" izz="0.001"/>
    </inertial>
  </link>
  <joint name="offset_to_right_battery" type="fixed">
    <parent link="right_battery_offset"/>
    <child link="right_battery"/>
    <origin xyz="0                    -0.0235                    -0.008"/>
  </joint>
  <link name="right_battery">
    <visual>
      <geometry>
        <box size="0.16 0.047 0.024"/>
      </geometry>
      <material name="battery_mat"/>
    </visual>
    <collision>
      <geometry>
        <box size="0.16 0.047 0.024"/>
      </geometry>
    </collision>
    <inertial>
      <origin/>
      <mass value="0.5025"/>
      <inertia ixx="0.000116621875" ixy="0" ixz="0" iyy="0.00109612" iyz="0" izz="0.001164501875"/>
    </inertial>
  </link>
  <gazebo reference="right_battery">
    <material>Gazebo/Blue</material>
  </gazebo>
  <joint name="left_front_shock" type="prismatic">
    <parent link="chassis"/>
    <child link="left_steering_link"/>
    <origin xyz="0.1675                    0.1525                    -0.0235"/>
    <axis xyz="0 0 -1"/>
    <limit effort="12.5106" lower="-0.042" upper="0.042" velocity="1000"/>
  </joint>
  <transmission name="left_front_shock_trans">
    <type>transmission_interface/SimpleTransmission</type>
    <joint name="left_front_shock">
      <hardwareInterface>EffortJointInterface</hardwareInterface>
    </joint>
    <actuator name="left_front_shock_act">
      <!-- This hardwareInterface element exists for compatibility
             with ROS Hydro. -->
      <hardwareInterface>EffortJointInterface</hardwareInterface>
      <mechanicalReduction>1</mechanicalReduction>
    </actuator>
  </transmission>
  <link name="left_steering_link">
    <inertial>
      <mass value="0.001"/>
      <inertia ixx="0.001" ixy="0" ixz="0" iyy="0.001" iyz="0" izz="0.001"/>
    </inertial>
  </link>
  <joint name="left_steering_joint" type="revolute">
    <parent link="left_steering_link"/>
    <child link="left_front_axle_carrier"/>
    <axis xyz="0 0 1"/>
    <limit effort="0.5649" lower="-0.785398163" upper="0.785398163" velocity="4.553"/>
  </joint>
  <transmission name="left_steering_trans">
    <type>transmission_interface/SimpleTransmission</type>
    <joint name="left_steering_joint">
      <hardwareInterface>EffortJointInterface</hardwareInterface>
    </joint>
    <actuator name="left_steering_act">
      <!-- This hardwareInterface element exists for compatibility
             with ROS Hydro. -->
      <hardwareInterface>EffortJointInterface</hardwareInterface>
      <mechanicalReduction>1</mechanicalReduction>
    </actuator>
  </transmission>
  <link name="left_front_axle_carrier">
    <inertial>
      <mass value="0.001"/>
      <inertia ixx="0.001" ixy="0" ixz="0" iyy="0.001" iyz="0" izz="0.001"/>
    </inertial>
  </link>
  <!-- The left and right axles have the same axis so that identical
         rotation values cause the wheels to rotate in the same direction. -->
  <joint name="left_front_axle" type="continuous">
    <parent link="left_front_axle_carrier"/>
    <child link="left_front_wheel"/>
    <origin rpy="1.57079633 0 0"/>
    <axis xyz="0 0 -1"/>
    <limit effort="5.12766" velocity="244.8696"/>
  </joint>
  <transmission name="left_front_axle_trans">
    <type>transmission_interface/SimpleTransmission</type>
    <joint name="left_front_axle">
      <hardwareInterface>EffortJointInterface</hardwareInterface>
    </joint>
    <actuator name="left_front_axle_act">
      <!-- This hardwareInterface element exists for compatibility
             with ROS Hydro. -->
      <hardwareInterface>EffortJointInterface</hardwareInterface>
      <mechanicalReduction>1</mechanicalReduction>
    </actuator>
  </transmission>
  <link name="left_front_wheel">
    <visual>
      <origin xyz="0                      -6.93889390391e-18                      0"/>
      <geometry>
        <cylinder length="0.0889" radius="0.073025"/>
      </geometry>
      <material name="tire_mat"/>
    </visual>
    <collision>
      <origin xyz="0                      -6.93889390391e-18                      0"/>
      <geometry>
        <cylinder length="0.0889" radius="0.073025"/>
      </geometry>
    </collision>
    <inertial>
      <mass value="0.29"/>
      <inertia ixx="0.000746465912979" ixy="0" ixz="0" iyy="0.000746465912979" iyz="0" izz="0.00111094334263"/>
    </inertial>
  </link>
  <gazebo reference="left_front_wheel">
    <material>Gazebo/Black</material>
  </gazebo>
  <joint name="right_front_shock" type="prismatic">
    <parent link="chassis"/>
    <child link="right_steering_link"/>
    <origin xyz="0.1675                    -0.1525                    -0.0235"/>
    <axis xyz="0 0 -1"/>
    <limit effort="12.5106" lower="-0.042" upper="0.042" velocity="1000"/>
  </joint>
  <transmission name="right_front_shock_trans">
    <type>transmission_interface/SimpleTransmission</type>
    <joint name="right_front_shock">
      <hardwareInterface>EffortJointInterface</hardwareInterface>
    </joint>
    <actuator name="right_front_shock_act">
      <!-- This hardwareInterface element exists for compatibility
             with ROS Hydro. -->
      <hardwareInterface>EffortJointInterface</hardwareInterface>
      <mechanicalReduction>1</mechanicalReduction>
    </actuator>
  </transmission>
  <link name="right_steering_link">
    <inertial>
      <mass value="0.001"/>
      <inertia ixx="0.001" ixy="0" ixz="0" iyy="0.001" iyz="0" izz="0.001"/>
    </inertial>
  </link>
  <joint name="right_steering_joint" type="revolute">
    <parent link="right_steering_link"/>
    <child link="right_front_axle_carrier"/>
    <axis xyz="0 0 1"/>
    <limit effort="0.5649" lower="-0.785398163" upper="0.785398163" velocity="4.553"/>
  </joint>
  <transmission name="right_steering_trans">
    <type>transmission_interface/SimpleTransmission</type>
    <joint name="right_steering_joint">
      <hardwareInterface>EffortJointInterface</hardwareInterface>
    </joint>
    <actuator name="right_steering_act">
      <!-- This hardwareInterface element exists for compatibility
             with ROS Hydro. -->
      <hardwareInterface>EffortJointInterface</hardwareInterface>
      <mechanicalReduction>1</mechanicalReduction>
    </actuator>
  </transmission>
  <link name="right_front_axle_carrier">
    <inertial>
      <mass value="0.001"/>
      <inertia ixx="0.001" ixy="0" ixz="0" iyy="0.001" iyz="0" izz="0.001"/>
    </inertial>
  </link>
  <!-- The left and right axles have the same axis so that identical
         rotation values cause the wheels to rotate in the same direction. -->
  <joint name="right_front_axle" type="continuous">
    <parent link="right_front_axle_carrier"/>
    <child link="right_front_wheel"/>
    <origin rpy="1.57079633 0 0"/>
    <axis xyz="0 0 -1"/>
    <limit effort="5.12766" velocity="244.8696"/>
  </joint>
  <transmission name="right_front_axle_trans">
    <type>transmission_interface/SimpleTransmission</type>
    <joint name="right_front_axle">
      <hardwareInterface>EffortJointInterface</hardwareInterface>
    </joint>
    <actuator name="right_front_axle_act">
      <!-- This hardwareInterface element exists for compatibility
             with ROS Hydro. -->
      <hardwareInterface>EffortJointInterface</hardwareInterface>
      <mechanicalReduction>1</mechanicalReduction>
    </actuator>
  </transmission>
  <link name="right_front_wheel">
    <visual>
      <origin xyz="0                      6.93889390391e-18                      0"/>
      <geometry>
        <cylinder length="0.0889" radius="0.073025"/>
      </geometry>
      <material name="tire_mat"/>
    </visual>
    <collision>
      <origin xyz="0                      6.93889390391e-18                      0"/>
      <geometry>
        <cylinder length="0.0889" radius="0.073025"/>
      </geometry>
    </collision>
    <inertial>
      <mass value="0.29"/>
      <inertia ixx="0.000746465912979" ixy="0" ixz="0" iyy="0.000746465912979" iyz="0" izz="0.00111094334263"/>
    </inertial>
  </link>
  <gazebo reference="right_front_wheel">
    <material>Gazebo/Black</material>
  </gazebo>
  <joint name="left_rear_shock" type="prismatic">
    <parent link="chassis"/>
    <child link="left_rear_axle_carrier"/>
    <origin xyz="-0.1675                    0.1525                    -0.0235"/>
    <axis xyz="0 0 -1"/>
    <limit effort="12.5106" lower="-0.042" upper="0.042" velocity="1000"/>
  </joint>
  <transmission name="left_rear_shock_trans">
    <type>transmission_interface/SimpleTransmission</type>
    <joint name="left_rear_shock">
      <hardwareInterface>EffortJointInterface</hardwareInterface>
    </joint>
    <actuator name="left_rear_shock_act">
      <!-- This hardwareInterface element exists for compatibility
             with ROS Hydro. -->
      <hardwareInterface>EffortJointInterface</hardwareInterface>
      <mechanicalReduction>1</mechanicalReduction>
    </actuator>
  </transmission>
  <link name="left_rear_axle_carrier">
    <inertial>
      <mass value="0.001"/>
      <inertia ixx="0.001" ixy="0" ixz="0" iyy="0.001" iyz="0" izz="0.001"/>
    </inertial>
  </link>
  <!-- The left and right axles have the same axis so that identical
         rotation values cause the wheels to rotate in the same direction. -->
  <joint name="left_rear_axle" type="continuous">
    <parent link="left_rear_axle_carrier"/>
    <child link="left_rear_wheel"/>
    <origin rpy="1.57079633 0 0"/>
    <axis xyz="0 0 -1"/>
    <limit effort="5.12766" velocity="244.8696"/>
  </joint>
  <transmission name="left_rear_axle_trans">
    <type>transmission_interface/SimpleTransmission</type>
    <joint name="left_rear_axle">
      <hardwareInterface>EffortJointInterface</hardwareInterface>
    </joint>
    <actuator name="left_rear_axle_act">
      <!-- This hardwareInterface element exists for compatibility
             with ROS Hydro. -->
      <hardwareInterface>EffortJointInterface</hardwareInterface>
      <mechanicalReduction>1</mechanicalReduction>
    </actuator>
  </transmission>
  <link name="left_rear_wheel">
    <visual>
      <origin xyz="0                      -6.93889390391e-18                      0"/>
      <geometry>
        <cylinder length="0.0889" radius="0.073025"/>
      </geometry>
      <material name="tire_mat"/>
    </visual>
    <collision>
      <origin xyz="0                      -6.93889390391e-18                      0"/>
      <geometry>
        <cylinder length="0.0889" radius="0.073025"/>
      </geometry>
    </collision>
    <inertial>
      <mass value="0.29"/>
      <inertia ixx="0.000746465912979" ixy="0" ixz="0" iyy="0.000746465912979" iyz="0" izz="0.00111094334263"/>
    </inertial>
  </link>
  <gazebo reference="left_rear_wheel">
    <material>Gazebo/Black</material>
  </gazebo>
  <joint name="right_rear_shock" type="prismatic">
    <parent link="chassis"/>
    <child link="right_rear_axle_carrier"/>
    <origin xyz="-0.1675                    -0.1525                    -0.0235"/>
    <axis xyz="0 0 -1"/>
    <limit effort="12.5106" lower="-0.042" upper="0.042" velocity="1000"/>
  </joint>
  <transmission name="right_rear_shock_trans">
    <type>transmission_interface/SimpleTransmission</type>
    <joint name="right_rear_shock">
      <hardwareInterface>EffortJointInterface</hardwareInterface>
    </joint>
    <actuator name="right_rear_shock_act">
      <!-- This hardwareInterface element exists for compatibility
             with ROS Hydro. -->
      <hardwareInterface>EffortJointInterface</hardwareInterface>
      <mechanicalReduction>1</mechanicalReduction>
    </actuator>
  </transmission>
  <link name="right_rear_axle_carrier">
    <inertial>
      <mass value="0.001"/>
      <inertia ixx="0.001" ixy="0" ixz="0" iyy="0.001" iyz="0" izz="0.001"/>
    </inertial>
  </link>
  <!-- The left and right axles have the same axis so that identical
         rotation values cause the wheels to rotate in the same direction. -->
  <joint name="right_rear_axle" type="continuous">
    <parent link="right_rear_axle_carrier"/>
    <child link="right_rear_wheel"/>
    <origin rpy="1.57079633 0 0"/>
    <axis xyz="0 0 -1"/>
    <limit effort="5.12766" velocity="244.8696"/>
  </joint>
  <transmission name="right_rear_axle_trans">
    <type>transmission_interface/SimpleTransmission</type>
    <joint name="right_rear_axle">
      <hardwareInterface>EffortJointInterface</hardwareInterface>
    </joint>
    <actuator name="right_rear_axle_act">
      <!-- This hardwareInterface element exists for compatibility
             with ROS Hydro. -->
      <hardwareInterface>EffortJointInterface</hardwareInterface>
      <mechanicalReduction>1</mechanicalReduction>
    </actuator>
  </transmission>
  <link name="right_rear_wheel">
    <visual>
      <origin xyz="0                      6.93889390391e-18                      0"/>
      <geometry>
        <cylinder length="0.0889" radius="0.073025"/>
      </geometry>
      <material name="tire_mat"/>
    </visual>
    <collision>
      <origin xyz="0                      6.93889390391e-18                      0"/>
      <geometry>
        <cylinder length="0.0889" radius="0.073025"/>
      </geometry>
    </collision>
    <inertial>
      <mass value="0.29"/>
      <inertia ixx="0.000746465912979" ixy="0" ixz="0" iyy="0.000746465912979" iyz="0" izz="0.00111094334263"/>
    </inertial>
  </link>
  <gazebo reference="right_rear_wheel">
    <material>Gazebo/Black</material>
  </gazebo>
  <!-- LiDAR -->
  <!-- <link name="hokuyo_link"> 
    <visual> 
      <geometry> 
        <box size="0.02 0.035 0.002"/> 
      </geometry> 
      <material name="Green"/> 
    </visual> 
    <inertial> 
      <mass value="0.001"/> 
      <origin xyz="0 0 0"/> 
      <inertia ixx="0.0001" ixy="0.0" ixz="0.0" iyy="0.0001" iyz="0.0" izz="0.0001"/> 
    </inertial> 
  </link>

  <joint name="laser_joint" type="fixed">
    <origin xyz="-0.065 0 0.075" rpy="0 0 0" />
    <parent link="base_link" />
    <child link="hokuyo_link" />
  </joint>
  
-->
  <gazebo>
    <plugin filename="libgazebo_ros_control.so" name="gazebo_ros_control"/>
  </gazebo>
  <joint name="hokuyo_laser_joint" type="fixed">
    <origin rpy="0 0 0" xyz="0 0 0.11"/>
    <parent link="base_link"/>
    <child link="hokuyo_laser_frame"/>
  </joint>
  <link name="hokuyo_laser_frame">
    <inertial>
      <mass value="0.270"/>
      <origin rpy="0 0 0" xyz="0 0 0"/>
      <inertia ixx="2.632e-4" ixy="0" ixz="0" iyy="2.632e-4" iyz="0" izz="1.62e-4"/>
    </inertial>
    <visual>
      <origin rpy="0 0 0" xyz="0 0 0"/>
      <geometry>
        <mesh filename="package://hector_sensors_description/meshes/hokuyo_utm30lx/hokuyo_utm_30lx.dae"/>
      </geometry>
    </visual>
    <collision>
      <origin rpy="0 0 0" xyz="0 0 -0.0115"/>
      <geometry>
        <box size="0.058 0.058 0.087"/>
        <!--<mesh filename="package://hector_sensors_description/meshes/hokuyo_utm30lx/hokuyo_utm_30lx.stl"/>-->
      </geometry>
    </collision>
  </link>
  <gazebo reference="hokuyo_laser_frame">
    <sensor name="hokuyo_laser" type="gpu_ray">
      <pose>0 0 0 0 0 0</pose>
      <visualize>true</visualize>
      <update_rate>40</update_rate>
      <ray>
        <scan>
          <horizontal>
            <samples>720</samples>
            <resolution>1</resolution>
            <min_angle>-1.570796</min_angle>
            <max_angle>1.570796</max_angle>
          </horizontal>
        </scan>
        <range>
          <min>0.10</min>
          <max>30.0</max>
          <resolution>0.01</resolution>
        </range>
        <noise>
          <type>gaussian</type>
          <!-- Noise parameters based on published spec for Hokuyo laser
                achieving "+-30mm" accuracy at range < 10m.  A mean of 0.0m and
                stddev of 0.01m will put 99.7% of samples within 0.03m of the true
                reading. -->
          <mean>0.0</mean>
          <stddev>0.01</stddev>
        </noise>
      </ray>
      <plugin filename="libgazebo_ros_gpu_laser.so" name="gazebo_ros_head_hokuyo_controller">
        <topicName>/ackermann_vehicle/scan</topicName>
        <frameName>hokuyo_laser_frame</frameName>
      </plugin>
    </sensor>
  </gazebo>
  <!-- IMU frame -->
  <link name="imu_link">
    <visual>
      <geometry>
        <box size="0.02 0.035 0.002"/>
      </geometry>
      <material name="Green"/>
    </visual>
    <inertial>
      <mass value="0.001"/>
      <origin xyz="0 0 0"/>
      <inertia ixx="0.0001" ixy="0.0" ixz="0.0" iyy="0.0001" iyz="0.0" izz="0.0001"/>
    </inertial>
  </link>
  <joint name="imu_joint" type="fixed">
    <origin rpy="0 0 0" xyz="-0.065 0 0.075"/>
    <parent link="base_link"/>
    <child link="imu_link"/>
  </joint>
  <gazebo reference="imu_link">
    <gravity>true</gravity>
    <sensor name="imu_sensor" type="imu">
      <always_on>true</always_on>
      <update_rate>100</update_rate>
      <visualize>true</visualize>
      <plugin filename="libgazebo_ros_imu_sensor.so" name="imu_plugin">
        <topicName>/ackermann_vehicle/imu</topicName>
        <bodyName>imu_link</bodyName>
        <updateRateHZ>100.0</updateRateHZ>
        <gaussianNoise>0.0</gaussianNoise>
        <xyzOffset>0 0 0</xyzOffset>
        <rpyOffset>0 0 0</rpyOffset>
        <frameName>imu_link</frameName>
        <initialOrientationAsReference>false</initialOrientationAsReference>
      </plugin>
      <pose>0 0 0 0 0 0</pose>
    </sensor>
  </gazebo>
</robot>
